Workbook

Sheet Master Subtasks
A1: Original Row ID | B1: Source Worksheet Row | C1: Original Stage | D1: Original Purpose | E1: Original Task | F1: Original Task Description | G1: Original Classification | H1: Original Sprint Proposal | I1: Original Source Rationale | J1: Phase ID | K1: Phase Name | L1: Task ID | M1: Task Name | N1: Task Owner ID | O1: Task Owner Name | P1: Sub-task ID | Q1: Sprint | R1: Assignee ID | S1: Assignee Name | T1: Start Date | U1: Due Date | V1: Effort | W1: Priority | X1: Work Type | Y1: Dependencies | Z1: Deliverable | AA1: Acceptance Criteria | AB1: Initial Status | AC1: Assumptions / Notes
A2: ORIG-001 | B2: 2 | C2: Phân tích nghiệp vụ & thiết kế hệ thống | D2: Chốt hệ thống phải làm gì | E2: Xác định loại hệ thống | F2: Web App bán vé xem phim và quản lý rạp | G2: Bắt buộc | H2: Sprint 1 | I2: Chốt phạm vi, actor, yêu cầu và luồng nghiệp vụ. | J2: PH-01 | K2: Discovery & PA1 | L2: CIN-T-001 | M2: Chốt phạm vi hệ thống và tác nhân | N2: 24120271 | O2: Nguyen Trung Chinh | P2: CIN-SUB-001 | Q2: Sprint 1 | R2: 24120271 | S2: Nguyen Trung Chinh | T2: 46298 | U2: 46311 | V2: 2 | W2: High | X2: Analysis | Z2: Hoàn tất kết quả gốc: Web App bán vé xem phim và quản lý rạp. | AA2: Kết quả gốc được kiểm tra và có bằng chứng gắn với CIN-SUB-001; ngoại lệ được ghi rõ. | AB2: Planned | AC2: Planned only; no completion evidence was transferred.
A3: ORIG-002 | B3: 3 | C3: Phân tích nghiệp vụ & thiết kế hệ thống | E3: Xác định phạm vi hệ thống | F3: Quản lý phim, phòng chiếu, ghế, loại vé, suất chiếu, đặt vé, thanh toán và tài khoản | G3: Bắt buộc | H3: Sprint 1 | I3: Chốt phạm vi, actor, yêu cầu và luồng nghiệp vụ. | J3: PH-01 | K3: Discovery & PA1 | L3: CIN-T-001 | M3: Chốt phạm vi hệ thống và tác nhân | N3: 24120271 | O3: Nguyen Trung Chinh | P3: CIN-SUB-002 | Q3: Sprint 1 | R3: 24120244 | S3: Phan Van Viet | T3: 46298 | U3: 46311 | V3: 2 | W3: High | X3: Analysis | Z3: Hoàn tất kết quả gốc: Quản lý phim, phòng chiếu, ghế, loại vé, suất chiếu, đặt vé, thanh toán và tài khoản. | AA3: Kết quả gốc được kiểm tra và có bằng chứng gắn với CIN-SUB-002; ngoại lệ được ghi rõ. | AB3: Planned | AC3: Planned only; no completion evidence was transferred.
A4: ORIG-003 | B4: 4 | C4: Phân tích nghiệp vụ & thiết kế hệ thống | E4: Xác định Actor | F4: Customer, Staff, Manager, Admin | G4: Bắt buộc | H4: Sprint 1 | I4: Chốt phạm vi, actor, yêu cầu và luồng nghiệp vụ. | J4: PH-01 | K4: Discovery & PA1 | L4: CIN-T-001 | M4: Chốt phạm vi hệ thống và tác nhân | N4: 24120271 | O4: Nguyen Trung Chinh | P4: CIN-SUB-003 | Q4: Sprint 1 | R4: 24120255 | S4: Tran Thien An | T4: 46298 | U4: 46311 | V4: 2 | W4: High | X4: Analysis | Z4: Hoàn tất kết quả gốc: Customer, Staff, Manager, Admin. | AA4: Kết quả gốc được kiểm tra và có bằng chứng gắn với CIN-SUB-003; ngoại lệ được ghi rõ. | AB4: Planned | AC4: Planned only; no completion evidence was transferred.
A5: ORIG-004 | B5: 5 | C5: Phân tích nghiệp vụ & thiết kế hệ thống | E5: Xác định nghiệp vụ chính | F5: Xem phim, xem lịch chiếu, chọn ghế, đặt vé, thanh toán, quản lý phim, quản lý phòng,... | G5: Bắt buộc | H5: Sprint 1 | I5: Chốt phạm vi, actor, yêu cầu và luồng nghiệp vụ. | J5: PH-01 | K5: Discovery & PA1 | L5: CIN-T-001 | M5: Chốt phạm vi hệ thống và tác nhân | N5: 24120271 | O5: Nguyen Trung Chinh | P5: CIN-SUB-004 | Q5: Sprint 1 | R5: 24120235 | S5: Huynh Thanh Tu | T5: 46298 | U5: 46311 | V5: 2 | W5: High | X5: Analysis | Z5: Hoàn tất kết quả gốc: Xem phim, xem lịch chiếu, chọn ghế, đặt vé, thanh toán, quản lý phim, quản lý phòng,.... | AA5: Kết quả gốc được kiểm tra và có bằng chứng gắn với CIN-SUB-004; ngoại lệ được ghi rõ. | AB5: Planned | AC5: Planned only; no completion evidence was transferred.
A6: ORIG-005 | B6: 6 | C6: Phân tích nghiệp vụ & thiết kế hệ thống | E6: Xác định đối tượng dữ liệu | F6: Movie, Genre, CinemaRoom, Seat, SeatType, TicketType, Showtime, Booking, BookingDetail, Ticket, Payment, User, Role, Cinema, MovieGenre, UserRole, PaymentEvent, Refund | G6: Mở rộng | H6: Sprint 5 | I6: Hạng mục nâng cao/phụ thuộc môi trường; xác nhận rubric và khả năng trước khi cam kết. | J6: PH-01 | K6: Discovery & PA1 | L6: CIN-T-002 | M6: Đặc tả luồng nghiệp vụ khách hàng và quản trị | N6: 24120098 | O6: Nguyen Quoc Nam | P6: CIN-SUB-005 | Q6: Sprint 1 | R6: 24120098 | S6: Nguyen Quoc Nam | T6: 46298 | U6: 46311 | V6: 2 | W6: High | X6: Analysis | Y6: CIN-T-001 | Z6: Hoàn tất kết quả gốc: Movie, Genre, CinemaRoom, Seat, SeatType, TicketType, Showtime, Booking, BookingDetail, Ticket, Payment, User, Role, Cinema, MovieGenre, UserRole, PaymentEvent, Refund. | AA6: Kết quả gốc được kiểm tra và có bằng chứng gắn với CIN-SUB-005; ngoại lệ được ghi rõ. | AB6: Planned | AC6: Planned only; no completion evidence was transferred.
A7: ORIG-006 | B7: 7 | C7: Phân tích nghiệp vụ & thiết kế hệ thống | E7: Phân tích luồng khách hàng | F7: Đăng nhập → chọn phim → chọn suất → chọn ghế → chọn vé → thanh toán → nhận vé | G7: Bắt buộc | H7: Sprint 1 | I7: Chốt phạm vi, actor, yêu cầu và luồng nghiệp vụ. | J7: PH-01 | K7: Discovery & PA1 | L7: CIN-T-002 | M7: Đặc tả luồng nghiệp vụ khách hàng và quản trị | N7: 24120098 | O7: Nguyen Quoc Nam | P7: CIN-SUB-006 | Q7: Sprint 1 | R7: 24120271 | S7: Nguyen Trung Chinh | T7: 46298 | U7: 46311 | V7: 2 | W7: High | X7: Analysis | Y7: CIN-T-001 | Z7: Hoàn tất kết quả gốc: Đăng nhập → chọn phim → chọn suất → chọn ghế → chọn vé → thanh toán → nhận vé. | AA7: Kết quả gốc được kiểm tra và có bằng chứng gắn với CIN-SUB-006; ngoại lệ được ghi rõ. | AB7: Planned | AC7: Planned only; no completion evidence was transferred.
A8: ORIG-007 | B8: 8 | C8: Phân tích nghiệp vụ & thiết kế hệ thống | E8: Phân tích luồng quản trị | F8: Login → Dashboard → quản lý phim / phòng / ghế / suất chiếu / booking | G8: Bắt buộc | H8: Sprint 1 | I8: Chốt phạm vi, actor, yêu cầu và luồng nghiệp vụ. | J8: PH-01 | K8: Discovery & PA1 | L8: CIN-T-002 | M8: Đặc tả luồng nghiệp vụ khách hàng và quản trị | N8: 24120098 | O8: Nguyen Quoc Nam | P8: CIN-SUB-007 | Q8: Sprint 1 | R8: 24120244 | S8: Phan Van Viet | T8: 46298 | U8: 46311 | V8: 3 | W8: High | X8: Analysis | Y8: CIN-T-001 | Z8: Hoàn tất kết quả gốc: Login → Dashboard → quản lý phim / phòng / ghế / suất chiếu / booking. | AA8: Kết quả gốc được kiểm tra và có bằng chứng gắn với CIN-SUB-007; ngoại lệ được ghi rõ. | AB8: Planned | AC8: Planned only; no completion evidence was transferred.
A9: ORIG-008 | B9: 9 | C9: Phân tích nghiệp vụ & thiết kế hệ thống | E9: Phân tích nghiệp vụ đặt vé | F9: Xác định quy tắc đặt, giữ, thanh toán và hủy vé | G9: Bắt buộc | H9: Sprint 1 | I9: Chốt phạm vi, actor, yêu cầu và luồng nghiệp vụ. | J9: PH-01 | K9: Discovery & PA1 | L9: CIN-T-002 | M9: Đặc tả luồng nghiệp vụ khách hàng và quản trị | N9: 24120098 | O9: Nguyen Quoc Nam | P9: CIN-SUB-008 | Q9: Sprint 1 | R9: 24120255 | S9: Tran Thien An | T9: 46298 | U9: 46311 | V9: 2 | W9: High | X9: Analysis | Y9: CIN-T-001 | Z9: Hoàn tất kết quả gốc: Xác định quy tắc đặt, giữ, thanh toán và hủy vé. | AA9: Kết quả gốc được kiểm tra và có bằng chứng gắn với CIN-SUB-008; ngoại lệ được ghi rõ. | AB9: Planned | AC9: Planned only; no completion evidence was transferred.
A10: ORIG-009 | B10: 10 | C10: Phân tích nghiệp vụ & thiết kế hệ thống | E10: Phân tích nghiệp vụ phòng chiếu | F10: Phòng, sơ đồ ghế, loại ghế, sức chứa | G10: Bắt buộc | H10: Sprint 1 | I10: Chốt phạm vi, actor, yêu cầu và luồng nghiệp vụ. | J10: PH-01 | K10: Discovery & PA1 | L10: CIN-T-002 | M10: Đặc tả luồng nghiệp vụ khách hàng và quản trị | N10: 24120098 | O10: Nguyen Quoc Nam | P10: CIN-SUB-009 | Q10: Sprint 1 | R10: 24120235 | S10: Huynh Thanh Tu | T10: 46298 | U10: 46311 | V10: 2 | W10: High | X10: Analysis | Y10: CIN-T-001 | Z10: Hoàn tất kết quả gốc: Phòng, sơ đồ ghế, loại ghế, sức chứa. | AA10: Kết quả gốc được kiểm tra và có bằng chứng gắn với CIN-SUB-009; ngoại lệ được ghi rõ. | AB10: Planned | AC10: Planned only; no completion evidence was transferred.
A11: ORIG-010 | B11: 11 | C11: Phân tích nghiệp vụ & thiết kế hệ thống | E11: Phân tích nghiệp vụ lịch chiếu | F11: Phim + phòng + thời gian + trạng thái | G11: Bắt buộc | H11: Sprint 1 | I11: Chốt phạm vi, actor, yêu cầu và luồng nghiệp vụ. | J11: PH-01 | K11: Discovery & PA1 | L11: CIN-T-002 | M11: Đặc tả luồng nghiệp vụ khách hàng và quản trị | N11: 24120098 | O11: Nguyen Quoc Nam | P11: CIN-SUB-010 | Q11: Sprint 1 | R11: 24120098 | S11: Nguyen Quoc Nam | T11: 46298 | U11: 46311 | V11: 2 | W11: High | X11: Analysis | Y11: CIN-T-001 | Z11: Hoàn tất kết quả gốc: Phim + phòng + thời gian + trạng thái. | AA11: Kết quả gốc được kiểm tra và có bằng chứng gắn với CIN-SUB-010; ngoại lệ được ghi rõ. | AB11: Planned | AC11: Planned only; no completion evidence was transferred.
A12: ORIG-011 | B12: 12 | C12: Phân tích nghiệp vụ & thiết kế hệ thống | E12: Phân tích nghiệp vụ thanh toán | F12: created, pending, unknown, succeeded, failed, cancelled, refund | G12: Mở rộng | H12: Sprint 5 | I12: Hạng mục nâng cao/phụ thuộc môi trường; xác nhận rubric và khả năng trước khi cam kết. | J12: PH-01 | K12: Discovery & PA1 | L12: CIN-T-002 | M12: Đặc tả luồng nghiệp vụ khách hàng và quản trị | N12: 24120098 | O12: Nguyen Quoc Nam | P12: CIN-SUB-011 | Q12: Sprint 1 | R12: 24120271 | S12: Nguyen Trung Chinh | T12: 46298 | U12: 46311 | V12: 2 | W12: High | X12: Analysis | Y12: CIN-T-001 | Z12: Hoàn tất kết quả gốc: created, pending, unknown, succeeded, failed, cancelled, refund. | AA12: Kết quả gốc được kiểm tra và có bằng chứng gắn với CIN-SUB-011; ngoại lệ được ghi rõ. | AB12: Planned | AC12: Planned only; no completion evidence was transferred.
A13: ORIG-012 | B13: 13 | C13: Phân tích nghiệp vụ & thiết kế hệ thống | E13: Xác định chức năng hệ thống | F13: Functional Requirements | G13: Bắt buộc | H13: Sprint 1 | I13: Chốt phạm vi, actor, yêu cầu và luồng nghiệp vụ. | J13: PH-01 | K13: Discovery & PA1 | L13: CIN-T-003 | M13: Baseline yêu cầu, use case và kiến trúc sơ bộ | N13: 24120255 | O13: Tran Thien An | P13: CIN-SUB-012 | Q13: Sprint 1 | R13: 24120255 | S13: Tran Thien An | T13: 46298 | U13: 46311 | V13: 2 | W13: High | X13: Analysis / Design | Y13: CIN-T-002 | Z13: Hoàn tất kết quả gốc: Functional Requirements. | AA13: Kết quả gốc được kiểm tra và có bằng chứng gắn với CIN-SUB-012; ngoại lệ được ghi rõ. | AB13: Planned | AC13: Planned only; no completion evidence was transferred.
A14: ORIG-013 | B14: 14 | C14: Phân tích nghiệp vụ & thiết kế hệ thống | E14: Xác định yêu cầu phi chức năng | F14: Security, Performance, Availability, Usability,... | G14: Bắt buộc | H14: Sprint 1 | I14: Chốt phạm vi, actor, yêu cầu và luồng nghiệp vụ. | J14: PH-01 | K14: Discovery & PA1 | L14: CIN-T-003 | M14: Baseline yêu cầu, use case và kiến trúc sơ bộ | N14: 24120255 | O14: Tran Thien An | P14: CIN-SUB-013 | Q14: Sprint 1 | R14: 24120235 | S14: Huynh Thanh Tu | T14: 46298 | U14: 46311 | V14: 3 | W14: High | X14: Analysis / Design | Y14: CIN-T-002 | Z14: Hoàn tất kết quả gốc: Security, Performance, Availability, Usability,.... | AA14: Kết quả gốc được kiểm tra và có bằng chứng gắn với CIN-SUB-013; ngoại lệ được ghi rõ. | AB14: Planned | AC14: Planned only; no completion evidence was transferred.
A15: ORIG-014 | B15: 15 | C15: Phân tích nghiệp vụ & thiết kế hệ thống | E15: Xây dựng Use Case | F15: Hoàn thiện Use Case Diagram | G15: Bắt buộc | H15: Sprint 1 | I15: Chốt phạm vi, actor, yêu cầu và luồng nghiệp vụ. | J15: PH-01 | K15: Discovery & PA1 | L15: CIN-T-003 | M15: Baseline yêu cầu, use case và kiến trúc sơ bộ | N15: 24120255 | O15: Tran Thien An | P15: CIN-SUB-014 | Q15: Sprint 1 | R15: 24120098 | S15: Nguyen Quoc Nam | T15: 46298 | U15: 46311 | V15: 2 | W15: High | X15: Analysis / Design | Y15: CIN-T-002 | Z15: Hoàn tất kết quả gốc: Hoàn thiện Use Case Diagram. | AA15: Kết quả gốc được kiểm tra và có bằng chứng gắn với CIN-SUB-014; ngoại lệ được ghi rõ. | AB15: Planned | AC15: Planned only; no completion evidence was transferred.
A16: ORIG-015 | B16: 16 | C16: Phân tích nghiệp vụ & thiết kế hệ thống | E16: Xây dựng Activity Diagram | F16: Các luồng nghiệp vụ chính | G16: Bắt buộc | H16: Sprint 1 | I16: Chốt phạm vi, actor, yêu cầu và luồng nghiệp vụ. | J16: PH-01 | K16: Discovery & PA1 | L16: CIN-T-003 | M16: Baseline yêu cầu, use case và kiến trúc sơ bộ | N16: 24120255 | O16: Tran Thien An | P16: CIN-SUB-015 | Q16: Sprint 1 | R16: 24120244 | S16: Phan Van Viet | T16: 46298 | U16: 46311 | V16: 2 | W16: High | X16: Analysis / Design | Y16: CIN-T-002 | Z16: Hoàn tất kết quả gốc: Các luồng nghiệp vụ chính. | AA16: Kết quả gốc được kiểm tra và có bằng chứng gắn với CIN-SUB-015; ngoại lệ được ghi rõ. | AB16: Planned | AC16: Planned only; no completion evidence was transferred.
A17: ORIG-016 | B17: 17 | C17: Phân tích nghiệp vụ & thiết kế hệ thống | E17: Xây dựng Sequence Diagram | F17: Booking, Payment, Authentication,... | G17: Bắt buộc | H17: Sprint 1 | I17: Chốt phạm vi, actor, yêu cầu và luồng nghiệp vụ. | J17: PH-01 | K17: Discovery & PA1 | L17: CIN-T-003 | M17: Baseline yêu cầu, use case và kiến trúc sơ bộ | N17: 24120255 | O17: Tran Thien An | P17: CIN-SUB-016 | Q17: Sprint 1 | R17: 24120271 | S17: Nguyen Trung Chinh | T17: 46298 | U17: 46311 | V17: 3 | W17: High | X17: Analysis / Design | Y17: CIN-T-002 | Z17: Hoàn tất kết quả gốc: Booking, Payment, Authentication,.... | AA17: Kết quả gốc được kiểm tra và có bằng chứng gắn với CIN-SUB-016; ngoại lệ được ghi rõ. | AB17: Planned | AC17: Planned only; no completion evidence was transferred.
A18: ORIG-017 | B18: 18 | C18: Phân tích nghiệp vụ & thiết kế hệ thống | E18: Thiết kế kiến trúc hệ thống | F18: Frontend → ASP.NET Core API → Business Logic → EF Core → PostgreSQL | G18: Bắt buộc | H18: Sprint 1 | I18: Chốt phạm vi, actor, yêu cầu và luồng nghiệp vụ. | J18: PH-01 | K18: Discovery & PA1 | L18: CIN-T-003 | M18: Baseline yêu cầu, use case và kiến trúc sơ bộ | N18: 24120255 | O18: Tran Thien An | P18: CIN-SUB-017 | Q18: Sprint 1 | R18: 24120255 | S18: Tran Thien An | T18: 46298 | U18: 46311 | V18: 3 | W18: High | X18: Analysis / Design | Y18: CIN-T-002 | Z18: Hoàn tất kết quả gốc: Frontend → ASP.NET Core API → Business Logic → EF Core → PostgreSQL. | AA18: Kết quả gốc được kiểm tra và có bằng chứng gắn với CIN-SUB-017; ngoại lệ được ghi rõ. | AB18: Planned | AC18: Planned only; no completion evidence was transferred.
A19: ORIG-018 | B19: 19 | C19: Thiết kế Database | D19: Chốt dữ liệu và quan hệ | E19: Thiết kế bảng | F19: Tổng hợp cấu trúc của toàn bộ bảng | G19: Bắt buộc | H19: Sprint 2 | I19: Nền tảng dữ liệu cho các nghiệp vụ cốt lõi. | J19: PH-02 | K19: Solution Design & Foundations | L19: CIN-T-004 | M19: Thiết kế dữ liệu phim, phòng, ghế và suất chiếu | N19: 24120235 | O19: Huynh Thanh Tu | P19: CIN-SUB-018 | Q19: Sprint 2 | R19: 24120098 | S19: Nguyen Quoc Nam | T19: 46312 | U19: 46325 | V19: 2 | W19: High | X19: Database Design | Y19: CIN-T-003 | Z19: Hoàn tất kết quả gốc: Tổng hợp cấu trúc của toàn bộ bảng. | AA19: Kết quả gốc được kiểm tra và có bằng chứng gắn với CIN-SUB-018; ngoại lệ được ghi rõ. | AB19: Planned | AC19: Planned only; no completion evidence was transferred.
A20: ORIG-019 | B20: 20 | C20: Thiết kế Database | E20: Thiết kế bảng Movie | F20: Tên phim, mô tả, thời lượng, ngày phát hành, trạng thái,... | G20: Bắt buộc | H20: Sprint 2 | I20: Nền tảng dữ liệu cho các nghiệp vụ cốt lõi. | J20: PH-02 | K20: Solution Design & Foundations | L20: CIN-T-004 | M20: Thiết kế dữ liệu phim, phòng, ghế và suất chiếu | N20: 24120235 | O20: Huynh Thanh Tu | P20: CIN-SUB-019 | Q20: Sprint 2 | R20: 24120244 | S20: Phan Van Viet | T20: 46312 | U20: 46325 | V20: 2 | W20: High | X20: Database Design | Y20: CIN-T-003 | Z20: Hoàn tất kết quả gốc: Tên phim, mô tả, thời lượng, ngày phát hành, trạng thái,.... | AA20: Kết quả gốc được kiểm tra và có bằng chứng gắn với CIN-SUB-019; ngoại lệ được ghi rõ. | AB20: Planned | AC20: Planned only; no completion evidence was transferred.
A21: ORIG-020 | B21: 21 | C21: Thiết kế Database | E21: Thiết kế bảng Genre | F21: Thể loại phim | G21: Bắt buộc | H21: Sprint 2 | I21: Nền tảng dữ liệu cho các nghiệp vụ cốt lõi. | J21: PH-02 | K21: Solution Design & Foundations | L21: CIN-T-004 | M21: Thiết kế dữ liệu phim, phòng, ghế và suất chiếu | N21: 24120235 | O21: Huynh Thanh Tu | P21: CIN-SUB-020 | Q21: Sprint 2 | R21: 24120235 | S21: Huynh Thanh Tu | T21: 46312 | U21: 46325 | V21: 2 | W21: High | X21: Database Design | Y21: CIN-T-003 | Z21: Hoàn tất kết quả gốc: Thể loại phim. | AA21: Kết quả gốc được kiểm tra và có bằng chứng gắn với CIN-SUB-020; ngoại lệ được ghi rõ. | AB21: Planned | AC21: Planned only; no completion evidence was transferred.
A22: ORIG-021 | B22: 22 | C22: Thiết kế Database | E22: Thiết kế bảng MovieGenre | F22: Quan hệ Movie – Genre nếu sử dụng N-N | G22: Bắt buộc | H22: Sprint 2 | I22: Nền tảng dữ liệu cho các nghiệp vụ cốt lõi. | J22: PH-02 | K22: Solution Design & Foundations | L22: CIN-T-004 | M22: Thiết kế dữ liệu phim, phòng, ghế và suất chiếu | N22: 24120235 | O22: Huynh Thanh Tu | P22: CIN-SUB-021 | Q22: Sprint 2 | R22: 24120255 | S22: Tran Thien An | T22: 46312 | U22: 46325 | V22: 2 | W22: High | X22: Database Design | Y22: CIN-T-003 | Z22: Hoàn tất kết quả gốc: Quan hệ Movie – Genre nếu sử dụng N-N. | AA22: Kết quả gốc được kiểm tra và có bằng chứng gắn với CIN-SUB-021; ngoại lệ được ghi rõ. | AB22: Planned | AC22: Planned only; no completion evidence was transferred.
A23: ORIG-022 | B23: 23 | C23: Thiết kế Database | E23: Thiết kế bảng CinemaRoom | F23: Tên phòng, sức chứa, trạng thái | G23: Bắt buộc | H23: Sprint 2 | I23: Nền tảng dữ liệu cho các nghiệp vụ cốt lõi. | J23: PH-02 | K23: Solution Design & Foundations | L23: CIN-T-004 | M23: Thiết kế dữ liệu phim, phòng, ghế và suất chiếu | N23: 24120235 | O23: Huynh Thanh Tu | P23: CIN-SUB-022 | Q23: Sprint 2 | R23: 24120271 | S23: Nguyen Trung Chinh | T23: 46312 | U23: 46325 | V23: 2 | W23: High | X23: Database Design | Y23: CIN-T-003 | Z23: Hoàn tất kết quả gốc: Tên phòng, sức chứa, trạng thái. | AA23: Kết quả gốc được kiểm tra và có bằng chứng gắn với CIN-SUB-022; ngoại lệ được ghi rõ. | AB23: Planned | AC23: Planned only; no completion evidence was transferred.
A24: ORIG-023 | B24: 24 | C24: Thiết kế Database | E24: Thiết kế bảng Seat | F24: Hàng, số ghế, loại ghế, phòng | G24: Bắt buộc | H24: Sprint 2 | I24: Nền tảng dữ liệu cho các nghiệp vụ cốt lõi. | J24: PH-02 | K24: Solution Design & Foundations | L24: CIN-T-004 | M24: Thiết kế dữ liệu phim, phòng, ghế và suất chiếu | N24: 24120235 | O24: Huynh Thanh Tu | P24: CIN-SUB-023 | Q24: Sprint 2 | R24: 24120098 | S24: Nguyen Quoc Nam | T24: 46312 | U24: 46325 | V24: 2 | W24: High | X24: Database Design | Y24: CIN-T-003 | Z24: Hoàn tất kết quả gốc: Hàng, số ghế, loại ghế, phòng. | AA24: Kết quả gốc được kiểm tra và có bằng chứng gắn với CIN-SUB-023; ngoại lệ được ghi rõ. | AB24: Planned | AC24: Planned only; no completion evidence was transferred.
A25: ORIG-024 | B25: 25 | C25: Thiết kế Database | E25: Thiết kế bảng SeatType | F25: Standard, VIP, Couple,... | G25: Bắt buộc | H25: Sprint 2 | I25: Nền tảng dữ liệu cho các nghiệp vụ cốt lõi. | J25: PH-02 | K25: Solution Design & Foundations | L25: CIN-T-004 | M25: Thiết kế dữ liệu phim, phòng, ghế và suất chiếu | N25: 24120235 | O25: Huynh Thanh Tu | P25: CIN-SUB-024 | Q25: Sprint 2 | R25: 24120244 | S25: Phan Van Viet | T25: 46312 | U25: 46325 | V25: 2 | W25: High | X25: Database Design | Y25: CIN-T-003 | Z25: Hoàn tất kết quả gốc: Standard, VIP, Couple,.... | AA25: Kết quả gốc được kiểm tra và có bằng chứng gắn với CIN-SUB-024; ngoại lệ được ghi rõ. | AB25: Planned | AC25: Planned only; no completion evidence was transferred.
A26: ORIG-025 | B26: 26 | C26: Thiết kế Database | E26: Thiết kế bảng TicketType | F26: Adult, Child, Student,... | G26: Bắt buộc | H26: Sprint 2 | I26: Nền tảng dữ liệu cho các nghiệp vụ cốt lõi. | J26: PH-02 | K26: Solution Design & Foundations | L26: CIN-T-004 | M26: Thiết kế dữ liệu phim, phòng, ghế và suất chiếu | N26: 24120235 | O26: Huynh Thanh Tu | P26: CIN-SUB-025 | Q26: Sprint 2 | R26: 24120235 | S26: Huynh Thanh Tu | T26: 46312 | U26: 46325 | V26: 3 | W26: High | X26: Database Design | Y26: CIN-T-003 | Z26: Hoàn tất kết quả gốc: Adult, Child, Student,.... | AA26: Kết quả gốc được kiểm tra và có bằng chứng gắn với CIN-SUB-025; ngoại lệ được ghi rõ. | AB26: Planned | AC26: Planned only; no completion evidence was transferred.
A27: ORIG-026 | B27: 27 | C27: Thiết kế Database | E27: Thiết kế bảng Showtime | F27: Phim, phòng, thời gian bắt đầu, kết thúc, trạng thái | G27: Bắt buộc | H27: Sprint 2 | I27: Nền tảng dữ liệu cho các nghiệp vụ cốt lõi. | J27: PH-02 | K27: Solution Design & Foundations | L27: CIN-T-004 | M27: Thiết kế dữ liệu phim, phòng, ghế và suất chiếu | N27: 24120235 | O27: Huynh Thanh Tu | P27: CIN-SUB-026 | Q27: Sprint 2 | R27: 24120255 | S27: Tran Thien An | T27: 46312 | U27: 46325 | V27: 2 | W27: High | X27: Database Design | Y27: CIN-T-003 | Z27: Hoàn tất kết quả gốc: Phim, phòng, thời gian bắt đầu, kết thúc, trạng thái. | AA27: Kết quả gốc được kiểm tra và có bằng chứng gắn với CIN-SUB-026; ngoại lệ được ghi rõ. | AB27: Planned | AC27: Planned only; no completion evidence was transferred.
A28: ORIG-027 | B28: 28 | C28: Thiết kế Database | E28: Thiết kế bảng Booking | F28: Customer, thời gian đặt, tổng tiền, trạng thái | G28: Bắt buộc | H28: Sprint 2 | I28: Nền tảng dữ liệu cho các nghiệp vụ cốt lõi. | J28: PH-02 | K28: Solution Design & Foundations | L28: CIN-T-005 | M28: Thiết kế dữ liệu booking, ticket, payment và user | N28: 24120271 | O28: Nguyen Trung Chinh | P28: CIN-SUB-027 | Q28: Sprint 2 | R28: 24120271 | S28: Nguyen Trung Chinh | T28: 46312 | U28: 46325 | V28: 3 | W28: High | X28: Database Design | Y28: CIN-T-004 | Z28: Hoàn tất kết quả gốc: Customer, thời gian đặt, tổng tiền, trạng thái. | AA28: Kết quả gốc được kiểm tra và có bằng chứng gắn với CIN-SUB-027; ngoại lệ được ghi rõ. | AB28: Planned | AC28: Planned only; no completion evidence was transferred.
A29: ORIG-028 | B29: 29 | C29: Thiết kế Database | E29: Thiết kế bảng BookingDetail | F29: Ghế, loại vé, giá snapshot, sức chứa | G29: Bắt buộc | H29: Sprint 2 | I29: Nền tảng dữ liệu cho các nghiệp vụ cốt lõi. | J29: PH-02 | K29: Solution Design & Foundations | L29: CIN-T-005 | M29: Thiết kế dữ liệu booking, ticket, payment và user | N29: 24120271 | O29: Nguyen Trung Chinh | P29: CIN-SUB-028 | Q29: Sprint 2 | R29: 24120098 | S29: Nguyen Quoc Nam | T29: 46312 | U29: 46325 | V29: 3 | W29: High | X29: Database Design | Y29: CIN-T-004 | Z29: Hoàn tất kết quả gốc: Ghế, loại vé, giá snapshot, sức chứa. | AA29: Kết quả gốc được kiểm tra và có bằng chứng gắn với CIN-SUB-028; ngoại lệ được ghi rõ. | AB29: Planned | AC29: Planned only; no completion evidence was transferred. Conditional/optional; confirm rubric, infrastructure and remaining capacity.
A30: ORIG-029 | B30: 30 | C30: Thiết kế Database | E30: Thiết kế bảng Ticket | F30: Mã vé, booking, ghế, QR Code, trạng thái | G30: Bắt buộc | H30: Sprint 2 | I30: Nền tảng dữ liệu cho các nghiệp vụ cốt lõi. | J30: PH-02 | K30: Solution Design & Foundations | L30: CIN-T-005 | M30: Thiết kế dữ liệu booking, ticket, payment và user | N30: 24120271 | O30: Nguyen Trung Chinh | P30: CIN-SUB-029 | Q30: Sprint 2 | R30: 24120244 | S30: Phan Van Viet | T30: 46312 | U30: 46325 | V30: 3 | W30: High | X30: Database Design | Y30: CIN-T-004 | Z30: Hoàn tất kết quả gốc: Mã vé, booking, ghế, QR Code, trạng thái. | AA30: Kết quả gốc được kiểm tra và có bằng chứng gắn với CIN-SUB-029; ngoại lệ được ghi rõ. | AB30: Planned | AC30: Planned only; no completion evidence was transferred.
A31: ORIG-030 | B31: 31 | C31: Thiết kế Database | E31: Thiết kế bảng Payment | F31: Mã giao dịch, số tiền, phương thức, trạng thái | G31: Bắt buộc | H31: Sprint 2 | I31: Nền tảng dữ liệu cho các nghiệp vụ cốt lõi. | J31: PH-02 | K31: Solution Design & Foundations | L31: CIN-T-005 | M31: Thiết kế dữ liệu booking, ticket, payment và user | N31: 24120271 | O31: Nguyen Trung Chinh | P31: CIN-SUB-030 | Q31: Sprint 2 | R31: 24120255 | S31: Tran Thien An | T31: 46312 | U31: 46325 | V31: 3 | W31: High | X31: Database Design | Y31: CIN-T-004 | Z31: Hoàn tất kết quả gốc: Mã giao dịch, số tiền, phương thức, trạng thái. | AA31: Kết quả gốc được kiểm tra và có bằng chứng gắn với CIN-SUB-030; ngoại lệ được ghi rõ. | AB31: Planned | AC31: Planned only; no completion evidence was transferred.
... A47: ORIG-046 | B47: 47 | C47: Thiết kế Database | E47: Hoàn thiện Relational Schema | F47: Lược đồ quan hệ cuối cùng | G47: Bắt buộc | H47: Sprint 2 | I47: Nền tảng dữ liệu cho các nghiệp vụ cốt lõi. | J47: PH-02 | K47: Solution Design & Foundations | L47: CIN-T-007 | M47: Hoàn tất ERD và relational schema | N47: 24120271 | O47: Nguyen Trung Chinh | P47: CIN-SUB-046 | Q47: Sprint 2 | R47: 24120235 | S47: Huynh Thanh Tu | T47: 46312 | U47: 46325 | V47: 3 | W47: High | X47: Database Design | Y47: CIN-T-006 | Z47: Hoàn tất kết quả gốc: Lược đồ quan hệ cuối cùng. | AA47: Kết quả gốc được kiểm tra và có bằng chứng gắn với CIN-SUB-046; ngoại lệ được ghi rõ. | AB47: Planned | AC47: Planned only; no completion evidence was transferred.
A48: ORIG-047 | B48: 48 | C48: Customer Web – Foundation | D48: Chốt cấu trúc FE trước khi code | E48: Xác định Customer User Flow | F48: Home → Movie Detail → Showtime → Seat Selection → Ticket Type → Booking Confirmation → Payment → Payment Result → My Tickets | G48: Bắt buộc | H48: Sprint 2 | I48: Layout, navigation và cấu trúc màn hình khách hàng. | J48: PH-02 | K48: Solution Design & Foundations | L48: CIN-T-008 | M48: Thiết kế luồng, màn hình và điều hướng Customer | N48: 24120255 | O48: Tran Thien An | P48: CIN-SUB-047 | Q48: Sprint 2 | R48: 24120255 | S48: Tran Thien An | T48: 46312 | U48: 46325 | V48: 3 | W48: High | X48: UX / UI Design | Y48: CIN-T-003 | Z48: Hoàn tất kết quả gốc: Home → Movie Detail → Showtime → Seat Selection → Ticket Type → Booking Confirmation → Payment → Payment Result → My Tickets. | AA48: Kết quả gốc được kiểm tra và có bằng chứng gắn với CIN-SUB-047; ngoại lệ được ghi rõ. | AB48: Planned | AC48: Planned only; no completion evidence was transferred.
A49: ORIG-048 | B49: 49 | C49: Customer Web – Foundation | E49: Xác định danh sách màn hình Customer | F49: Xác định toàn bộ màn hình cần có cho Customer | G49: Bắt buộc | H49: Sprint 2 | I49: Layout, navigation và cấu trúc màn hình khách hàng. | J49: PH-02 | K49: Solution Design & Foundations | L49: CIN-T-008 | M49: Thiết kế luồng, màn hình và điều hướng Customer | N49: 24120255 | O49: Tran Thien An | P49: CIN-SUB-048 | Q49: Sprint 2 | R49: 24120244 | S49: Phan Van Viet | T49: 46312 | U49: 46325 | V49: 2 | W49: High | X49: UX / UI Design | Y49: CIN-T-003 | Z49: Hoàn tất kết quả gốc: Xác định toàn bộ màn hình cần có cho Customer. | AA49: Kết quả gốc được kiểm tra và có bằng chứng gắn với CIN-SUB-048; ngoại lệ được ghi rõ. | AB49: Planned | AC49: Planned only; no completion evidence was transferred.
A50: ORIG-049 | B50: 50 | C50: Customer Web – Foundation | E50: Web Layout | F50: Header, Footer, Navigation, Responsive | G50: Bắt buộc | H50: Sprint 2 | I50: Layout, navigation và cấu trúc màn hình khách hàng. | J50: PH-02 | K50: Solution Design & Foundations | L50: CIN-T-008 | M50: Thiết kế luồng, màn hình và điều hướng Customer | N50: 24120255 | O50: Tran Thien An | P50: CIN-SUB-049 | Q50: Sprint 2 | R50: 24120098 | S50: Nguyen Quoc Nam | T50: 46312 | U50: 46325 | V50: 3 | W50: High | X50: UX / UI Design | Y50: CIN-T-003 | Z50: Hoàn tất kết quả gốc: Header, Footer, Navigation, Responsive. | AA50: Kết quả gốc được kiểm tra và có bằng chứng gắn với CIN-SUB-049; ngoại lệ được ghi rõ. | AB50: Planned | AC50: Planned only; no completion evidence was transferred.
A51: ORIG-050 | B51: 51 | C51: Customer Web – Foundation | E51: Navigation | F51: Xác định các menu và đường dẫn giữa các màn hình | G51: Bắt buộc | H51: Sprint 2 | I51: Layout, navigation và cấu trúc màn hình khách hàng. | J51: PH-02 | K51: Solution Design & Foundations | L51: CIN-T-008 | M51: Thiết kế luồng, màn hình và điều hướng Customer | N51: 24120255 | O51: Tran Thien An | P51: CIN-SUB-050 | Q51: Sprint 2 | R51: 24120271 | S51: Nguyen Trung Chinh | T51: 46312 | U51: 46325 | V51: 2 | W51: High | X51: UX / UI Design | Y51: CIN-T-003 | Z51: Hoàn tất kết quả gốc: Xác định các menu và đường dẫn giữa các màn hình. | AA51: Kết quả gốc được kiểm tra và có bằng chứng gắn với CIN-SUB-050; ngoại lệ được ghi rõ. | AB51: Planned | AC51: Planned only; no completion evidence was transferred.
A52: ORIG-051 | B52: 52 | C52: Customer Web – Foundation | E52: Trang Home | F52: Phim đang chiếu / sắp chiếu | G52: Bắt buộc | H52: Sprint 2 | I52: Layout, navigation và cấu trúc màn hình khách hàng. | J52: PH-02 | K52: Solution Design & Foundations | L52: CIN-T-009 | M52: Đặc tả các màn hình Customer | N52: 24120244 | O52: Phan Van Viet | P52: CIN-SUB-051 | Q52: Sprint 2 | R52: 24120244 | S52: Phan Van Viet | T52: 46312 | U52: 46325 | V52: 2 | W52: High | X52: UX / UI Design | Y52: CIN-T-008 | Z52: Hoàn tất kết quả gốc: Phim đang chiếu / sắp chiếu. | AA52: Kết quả gốc được kiểm tra và có bằng chứng gắn với CIN-SUB-051; ngoại lệ được ghi rõ. | AB52: Planned | AC52: Planned only; no completion evidence was transferred.
A53: ORIG-052 | B53: 53 | C53: Customer Web – Foundation | E53: Trang Movie List | F53: Danh sách phim | G53: Bắt buộc | H53: Sprint 2 | I53: Layout, navigation và cấu trúc màn hình khách hàng. | J53: PH-02 | K53: Solution Design & Foundations | L53: CIN-T-009 | M53: Đặc tả các màn hình Customer | N53: 24120244 | O53: Phan Van Viet | P53: CIN-SUB-052 | Q53: Sprint 2 | R53: 24120235 | S53: Huynh Thanh Tu | T53: 46312 | U53: 46325 | V53: 2 | W53: High | X53: UX / UI Design | Y53: CIN-T-008 | Z53: Hoàn tất kết quả gốc: Danh sách phim. | AA53: Kết quả gốc được kiểm tra và có bằng chứng gắn với CIN-SUB-052; ngoại lệ được ghi rõ. | AB53: Planned | AC53: Planned only; no completion evidence was transferred.
A54: ORIG-053 | B54: 54 | C54: Customer Web – Foundation | E54: Trang Movie Detail | F54: Thông tin chi tiết phim | G54: Bắt buộc | H54: Sprint 2 | I54: Layout, navigation và cấu trúc màn hình khách hàng. | J54: PH-02 | K54: Solution Design & Foundations | L54: CIN-T-009 | M54: Đặc tả các màn hình Customer | N54: 24120244 | O54: Phan Van Viet | P54: CIN-SUB-053 | Q54: Sprint 2 | R54: 24120255 | S54: Tran Thien An | T54: 46312 | U54: 46325 | V54: 2 | W54: High | X54: UX / UI Design | Y54: CIN-T-008 | Z54: Hoàn tất kết quả gốc: Thông tin chi tiết phim. | AA54: Kết quả gốc được kiểm tra và có bằng chứng gắn với CIN-SUB-053; ngoại lệ được ghi rõ. | AB54: Planned | AC54: Planned only; no completion evidence was transferred. Conditional/optional; confirm rubric, infrastructure and remaining capacity.
A55: ORIG-054 | B55: 55 | C55: Customer Web – Foundation | E55: Trang Showtime | F55: Lịch chiếu theo phim / ngày / rạp | G55: Bắt buộc | H55: Sprint 2 | I55: Layout, navigation và cấu trúc màn hình khách hàng. | J55: PH-02 | K55: Solution Design & Foundations | L55: CIN-T-009 | M55: Đặc tả các màn hình Customer | N55: 24120244 | O55: Phan Van Viet | P55: CIN-SUB-054 | Q55: Sprint 2 | R55: 24120271 | S55: Nguyen Trung Chinh | T55: 46312 | U55: 46325 | V55: 2 | W55: High | X55: UX / UI Design | Y55: CIN-T-008 | Z55: Hoàn tất kết quả gốc: Lịch chiếu theo phim / ngày / rạp. | AA55: Kết quả gốc được kiểm tra và có bằng chứng gắn với CIN-SUB-054; ngoại lệ được ghi rõ. | AB55: Planned | AC55: Planned only; no completion evidence was transferred.
...

Sheet Task Hierarchy
A1: Level | B1: Hierarchy ID | C1: Parent ID | D1: Name / Original Task | E1: Phase ID | F1: Phase Name | G1: Task ID | H1: Task Owner ID | I1: Task Owner Name | J1: Sprint | K1: Assignee ID | L1: Assignee Name | M1: Start Date | N1: Due Date | O1: Effort | P1: Original Row ID | Q1: Priority | R1: Status
A2: Phase | B2: PH-01 | D2: Discovery & PA1 | E2: PH-01 | F2: Discovery & PA1 | J2: Sprint 1 | M2: 46298 | N2: 46311 | O2: =SUMIFS('Master Subtasks'!$V$2:$V$293,'Master Subtasks'!$J$2:$J$293,$B2) | R2: Planned
A3: Task | B3: CIN-T-001 | C3: PH-01 | D3: Chốt phạm vi hệ thống và tác nhân | E3: PH-01 | F3: Discovery & PA1 | G3: CIN-T-001 | H3: 24120271 | I3: Nguyen Trung Chinh | J3: Sprint 1 | M3: 46298 | N3: 46311 | O3: =SUMIFS('Master Subtasks'!$V$2:$V$293,'Master Subtasks'!$L$2:$L$293,$B3) | Q3: High | R3: Planned
A4: Sub-task | B4: CIN-SUB-001 | C4: CIN-T-001 | D4: Xác định loại hệ thống | E4: PH-01 | F4: Discovery & PA1 | G4: CIN-T-001 | H4: 24120271 | I4: Nguyen Trung Chinh | J4: Sprint 1 | K4: 24120271 | L4: Nguyen Trung Chinh | M4: 46298 | N4: 46311 | O4: 2 | P4: ORIG-001 | Q4: High | R4: Planned
A5: Sub-task | B5: CIN-SUB-002 | C5: CIN-T-001 | D5: Xác định phạm vi hệ thống | E5: PH-01 | F5: Discovery & PA1 | G5: CIN-T-001 | H5: 24120271 | I5: Nguyen Trung Chinh | J5: Sprint 1 | K5: 24120244 | L5: Phan Van Viet | M5: 46298 | N5: 46311 | O5: 2 | P5: ORIG-002 | Q5: High | R5: Planned
A6: Sub-task | B6: CIN-SUB-003 | C6: CIN-T-001 | D6: Xác định Actor | E6: PH-01 | F6: Discovery & PA1 | G6: CIN-T-001 | H6: 24120271 | I6: Nguyen Trung Chinh | J6: Sprint 1 | K6: 24120255 | L6: Tran Thien An | M6: 46298 | N6: 46311 | O6: 2 | P6: ORIG-003 | Q6: High | R6: Planned
A7: Sub-task | B7: CIN-SUB-004 | C7: CIN-T-001 | D7: Xác định nghiệp vụ chính | E7: PH-01 | F7: Discovery & PA1 | G7: CIN-T-001 | H7: 24120271 | I7: Nguyen Trung Chinh | J7: Sprint 1 | K7: 24120235 | L7: Huynh Thanh Tu | M7: 46298 | N7: 46311 | O7: 2 | P7: ORIG-004 | Q7: High | R7: Planned
A8: Task | B8: CIN-T-002 | C8: PH-01 | D8: Đặc tả luồng nghiệp vụ khách hàng và quản trị | E8: PH-01 | F8: Discovery & PA1 | G8: CIN-T-002 | H8: 24120098 | I8: Nguyen Quoc Nam | J8: Sprint 1 | M8: 46298 | N8: 46311 | O8: =SUMIFS('Master Subtasks'!$V$2:$V$293,'Master Subtasks'!$L$2:$L$293,$B8) | Q8: High | R8: Planned
A9: Sub-task | B9: CIN-SUB-005 | C9: CIN-T-002 | D9: Xác định đối tượng dữ liệu | E9: PH-01 | F9: Discovery & PA1 | G9: CIN-T-002 | H9: 24120098 | I9: Nguyen Quoc Nam | J9: Sprint 1 | K9: 24120098 | L9: Nguyen Quoc Nam | M9: 46298 | N9: 46311 | O9: 2 | P9: ORIG-005 | Q9: High | R9: Planned
A10: Sub-task | B10: CIN-SUB-006 | C10: CIN-T-002 | D10: Phân tích luồng khách hàng | E10: PH-01 | F10: Discovery & PA1 | G10: CIN-T-002 | H10: 24120098 | I10: Nguyen Quoc Nam | J10: Sprint 1 | K10: 24120271 | L10: Nguyen Trung Chinh | M10: 46298 | N10: 46311 | O10: 2 | P10: ORIG-006 | Q10: High | R10: Planned
A11: Sub-task | B11: CIN-SUB-007 | C11: CIN-T-002 | D11: Phân tích luồng quản trị | E11: PH-01 | F11: Discovery & PA1 | G11: CIN-T-002 | H11: 24120098 | I11: Nguyen Quoc Nam | J11: Sprint 1 | K11: 24120244 | L11: Phan Van Viet | M11: 46298 | N11: 46311 | O11: 3 | P11: ORIG-007 | Q11: High | R11: Planned
A12: Sub-task | B12: CIN-SUB-008 | C12: CIN-T-002 | D12: Phân tích nghiệp vụ đặt vé | E12: PH-01 | F12: Discovery & PA1 | G12: CIN-T-002 | H12: 24120098 | I12: Nguyen Quoc Nam | J12: Sprint 1 | K12: 24120255 | L12: Tran Thien An | M12: 46298 | N12: 46311 | O12: 2 | P12: ORIG-008 | Q12: High | R12: Planned
A13: Sub-task | B13: CIN-SUB-009 | C13: CIN-T-002 | D13: Phân tích nghiệp vụ phòng chiếu | E13: PH-01 | F13: Discovery & PA1 | G13: CIN-T-002 | H13: 24120098 | I13: Nguyen Quoc Nam | J13: Sprint 1 | K13: 24120235 | L13: Huynh Thanh Tu | M13: 46298 | N13: 46311 | O13: 2 | P13: ORIG-009 | Q13: High | R13: Planned
A14: Sub-task | B14: CIN-SUB-010 | C14: CIN-T-002 | D14: Phân tích nghiệp vụ lịch chiếu | E14: PH-01 | F14: Discovery & PA1 | G14: CIN-T-002 | H14: 24120098 | I14: Nguyen Quoc Nam | J14: Sprint 1 | K14: 24120098 | L14: Nguyen Quoc Nam | M14: 46298 | N14: 46311 | O14: 2 | P14: ORIG-010 | Q14: High | R14: Planned
A15: Sub-task | B15: CIN-SUB-011 | C15: CIN-T-002 | D15: Phân tích nghiệp vụ thanh toán | E15: PH-01 | F15: Discovery & PA1 | G15: CIN-T-002 | H15: 24120098 | I15: Nguyen Quoc Nam | J15: Sprint 1 | K15: 24120271 | L15: Nguyen Trung Chinh | M15: 46298 | N15: 46311 | O15: 2 | P15: ORIG-011 | Q15: High | R15: Planned
A16: Task | B16: CIN-T-003 | C16: PH-01 | D16: Baseline yêu cầu, use case và kiến trúc sơ bộ | E16: PH-01 | F16: Discovery & PA1 | G16: CIN-T-003 | H16: 24120255 | I16: Tran Thien An | J16: Sprint 1 | M16: 46298 | N16: 46311 | O16: =SUMIFS('Master Subtasks'!$V$2:$V$293,'Master Subtasks'!$L$2:$L$293,$B16) | Q16: High | R16: Planned
A17: Sub-task | B17: CIN-SUB-012 | C17: CIN-T-003 | D17: Xác định chức năng hệ thống | E17: PH-01 | F17: Discovery & PA1 | G17: CIN-T-003 | H17: 24120255 | I17: Tran Thien An | J17: Sprint 1 | K17: 24120255 | L17: Tran Thien An | M17: 46298 | N17: 46311 | O17: 2 | P17: ORIG-012 | Q17: High | R17: Planned
A18: Sub-task | B18: CIN-SUB-013 | C18: CIN-T-003 | D18: Xác định yêu cầu phi chức năng | E18: PH-01 | F18: Discovery & PA1 | G18: CIN-T-003 | H18: 24120255 | I18: Tran Thien An | J18: Sprint 1 | K18: 24120235 | L18: Huynh Thanh Tu | M18: 46298 | N18: 46311 | O18: 3 | P18: ORIG-013 | Q18: High | R18: Planned
A19: Sub-task | B19: CIN-SUB-014 | C19: CIN-T-003 | D19: Xây dựng Use Case | E19: PH-01 | F19: Discovery & PA1 | G19: CIN-T-003 | H19: 24120255 | I19: Tran Thien An | J19: Sprint 1 | K19: 24120098 | L19: Nguyen Quoc Nam | M19: 46298 | N19: 46311 | O19: 2 | P19: ORIG-014 | Q19: High | R19: Planned
A20: Sub-task | B20: CIN-SUB-015 | C20: CIN-T-003 | D20: Xây dựng Activity Diagram | E20: PH-01 | F20: Discovery & PA1 | G20: CIN-T-003 | H20: 24120255 | I20: Tran Thien An | J20: Sprint 1 | K20: 24120244 | L20: Phan Van Viet | M20: 46298 | N20: 46311 | O20: 2 | P20: ORIG-015 | Q20: High | R20: Planned
A21: Sub-task | B21: CIN-SUB-016 | C21: CIN-T-003 | D21: Xây dựng Sequence Diagram | E21: PH-01 | F21: Discovery & PA1 | G21: CIN-T-003 | H21: 24120255 | I21: Tran Thien An | J21: Sprint 1 | K21: 24120271 | L21: Nguyen Trung Chinh | M21: 46298 | N21: 46311 | O21: 3 | P21: ORIG-016 | Q21: High | R21: Planned
A22: Sub-task | B22: CIN-SUB-017 | C22: CIN-T-003 | D22: Thiết kế kiến trúc hệ thống | E22: PH-01 | F22: Discovery & PA1 | G22: CIN-T-003 | H22: 24120255 | I22: Tran Thien An | J22: Sprint 1 | K22: 24120255 | L22: Tran Thien An | M22: 46298 | N22: 46311 | O22: 3 | P22: ORIG-017 | Q22: High | R22: Planned
A23: Task | B23: CIN-T-012 | C23: PH-01 | D23: Thiết lập quy tắc cộng tác và cấu trúc repository | E23: PH-01 | F23: Discovery & PA1 | G23: CIN-T-012 | H23: 24120098 | I23: Nguyen Quoc Nam | J23: Sprint 1 | M23: 46298 | N23: 46311 | O23: =SUMIFS('Master Subtasks'!$V$2:$V$293,'Master Subtasks'!$L$2:$L$293,$B23) | Q23: Medium | R23: Planned
A24: Sub-task | B24: CIN-SUB-072 | C24: CIN-T-012 | D24: Git Branching | E24: PH-01 | F24: Discovery & PA1 | G24: CIN-T-012 | H24: 24120098 | I24: Nguyen Quoc Nam | J24: Sprint 1 | K24: 24120098 | L24: Nguyen Quoc Nam | M24: 46298 | N24: 46311 | O24: 1 | P24: ORIG-072 | Q24: Medium | R24: Planned
A25: Sub-task | B25: CIN-SUB-073 | C25: CIN-T-012 | D25: Commit Convention | E25: PH-01 | F25: Discovery & PA1 | G25: CIN-T-012 | H25: 24120098 | I25: Nguyen Quoc Nam | J25: Sprint 1 | K25: 24120244 | L25: Phan Van Viet | M25: 46298 | N25: 46311 | O25: 1 | P25: ORIG-073 | Q25: Medium | R25: Planned
A26: Sub-task | B26: CIN-SUB-074 | C26: CIN-T-012 | D26: Pull Request | E26: PH-01 | F26: Discovery & PA1 | G26: CIN-T-012 | H26: 24120098 | I26: Nguyen Quoc Nam | J26: Sprint 1 | K26: 24120098 | L26: Nguyen Quoc Nam | M26: 46298 | N26: 46311 | O26: 2 | P26: ORIG-074 | Q26: Medium | R26: Planned
A27: Sub-task | B27: CIN-SUB-075 | C27: CIN-T-012 | D27: Merge Conflict Handling | E27: PH-01 | F27: Discovery & PA1 | G27: CIN-T-012 | H27: 24120098 | I27: Nguyen Quoc Nam | J27: Sprint 1 | K27: 24120235 | L27: Huynh Thanh Tu | M27: 46298 | N27: 46311 | O27: 1 | P27: ORIG-075 | Q27: Medium | R27: Planned
A28: Sub-task | B28: CIN-SUB-076 | C28: CIN-T-012 | D28: Repository Structure | E28: PH-01 | F28: Discovery & PA1 | G28: CIN-T-012 | H28: 24120098 | I28: Nguyen Quoc Nam | J28: Sprint 1 | K28: 24120244 | L28: Phan Van Viet | M28: 46298 | N28: 46311 | O28: 2 | P28: ORIG-076 | Q28: Medium | R28: Planned
A29: Sub-task | B29: CIN-SUB-077 | C29: CIN-T-012 | D29: Secrets Check | E29: PH-01 | F29: Discovery & PA1 | G29: CIN-T-012 | H29: 24120098 | I29: Nguyen Quoc Nam | J29: Sprint 1 | K29: 24120235 | L29: Huynh Thanh Tu | M29: 46298 | N29: 46311 | O29: 1 | P29: ORIG-077 | Q29: Medium | R29: Planned
A30: Task | B30: CIN-T-047 | C30: PH-01 | D30: Soạn tổng quan và phân tích nghiệp vụ cho PA1 | E30: PH-01 | F30: Discovery & PA1 | G30: CIN-T-047 | H30: 24120098 | I30: Nguyen Quoc Nam | J30: Sprint 1 | M30: 46298 | N30: 46311 | O30: =SUMIFS('Master Subtasks'!$V$2:$V$293,'Master Subtasks'!$L$2:$L$293,$B30) | Q30: High | R30: Planned
A31: Sub-task | B31: CIN-SUB-279 | C31: CIN-T-047 | D31: Tổng quan hệ thống | E31: PH-01 | F31: Discovery & PA1 | G31: CIN-T-047 | H31: 24120098 | I31: Nguyen Quoc Nam | J31: Sprint 1 | K31: 24120098 | L31: Nguyen Quoc Nam | M31: 46298 | N31: 46311 | O31: 2 | P31: ORIG-279 | Q31: High | R31: Planned
A32: Sub-task | B32: CIN-SUB-280 | C32: CIN-T-047 | D32: Phân tích nghiệp vụ | E32: PH-01 | F32: Discovery & PA1 | G32: CIN-T-047 | H32: 24120098 | I32: Nguyen Quoc Nam | J32: Sprint 1 | K32: 24120235 | L32: Huynh Thanh Tu | M32: 46298 | N32: 46311 | O32: 2 | P32: ORIG-280 | Q32: High | R32: Planned
A33: Phase | B33: PH-02 | D33: Solution Design & Foundations | E33: PH-02 | F33: Solution Design & Foundations | J33: Sprint 2, Sprint 3 | M33: 46312 | N33: 46339 | O33: =SUMIFS('Master Subtasks'!$V$2:$V$293,'Master Subtasks'!$J$2:$J$293,$B33) | R33: Planned
A34: Task | B34: CIN-T-004 | C34: PH-02 | D34: Thiết kế dữ liệu phim, phòng, ghế và suất chiếu | E34: PH-02 | F34: Solution Design & Foundations | G34: CIN-T-004 | H34: 24120235 | I34: Huynh Thanh Tu | J34: Sprint 2 | M34: 46312 | N34: 46325 | O34: =SUMIFS('Master Subtasks'!$V$2:$V$293,'Master Subtasks'!$L$2:$L$293,$B34) | Q34: High | R34: Planned
A35: Sub-task | B35: CIN-SUB-018 | C35: CIN-T-004 | D35: Thiết kế bảng | E35: PH-02 | F35: Solution Design & Foundations | G35: CIN-T-004 | H35: 24120235 | I35: Huynh Thanh Tu | J35: Sprint 2 | K35: 24120098 | L35: Nguyen Quoc Nam | M35: 46312 | N35: 46325 | O35: 2 | P35: ORIG-018 | Q35: High | R35: Planned
A36: Sub-task | B36: CIN-SUB-019 | C36: CIN-T-004 | D36: Thiết kế bảng Movie | E36: PH-02 | F36: Solution Design & Foundations | G36: CIN-T-004 | H36: 24120235 | I36: Huynh Thanh Tu | J36: Sprint 2 | K36: 24120244 | L36: Phan Van Viet | M36: 46312 | N36: 46325 | O36: 2 | P36: ORIG-019 | Q36: High | R36: Planned
A37: Sub-task | B37: CIN-SUB-020 | C37: CIN-T-004 | D37: Thiết kế bảng Genre | E37: PH-02 | F37: Solution Design & Foundations | G37: CIN-T-004 | H37: 24120235 | I37: Huynh Thanh Tu | J37: Sprint 2 | K37: 24120235 | L37: Huynh Thanh Tu | M37: 46312 | N37: 46325 | O37: 2 | P37: ORIG-020 | Q37: High | R37: Planned
A38: Sub-task | B38: CIN-SUB-021 | C38: CIN-T-004 | D38: Thiết kế bảng MovieGenre | E38: PH-02 | F38: Solution Design & Foundations | G38: CIN-T-004 | H38: 24120235 | I38: Huynh Thanh Tu | J38: Sprint 2 | K38: 24120255 | L38: Tran Thien An | M38: 46312 | N38: 46325 | O38: 2 | P38: ORIG-021 | Q38: High | R38: Planned
A39: Sub-task | B39: CIN-SUB-022 | C39: CIN-T-004 | D39: Thiết kế bảng CinemaRoom | E39: PH-02 | F39: Solution Design & Foundations | G39: CIN-T-004 | H39: 24120235 | I39: Huynh Thanh Tu | J39: Sprint 2 | K39: 24120271 | L39: Nguyen Trung Chinh | M39: 46312 | N39: 46325 | O39: 2 | P39: ORIG-022 | Q39: High | R39: Planned
A40: Sub-task | B40: CIN-SUB-023 | C40: CIN-T-004 | D40: Thiết kế bảng Seat | E40: PH-02 | F40: Solution Design & Foundations | G40: CIN-T-004 | H40: 24120235 | I40: Huynh Thanh Tu | J40: Sprint 2 | K40: 24120098 | L40: Nguyen Quoc Nam | M40: 46312 | N40: 46325 | O40: 2 | P40: ORIG-023 | Q40: High | R40: Planned
...

Sheet Sprint Plan
A1: Sprint | B1: Start Date | C1: End Date | D1: Sprint Goal | E1: Task IDs / Names | F1: Key Deliverables | G1: Critical Dependencies | H1: PA Milestone | I1: Total Effort (SP) | J1: Risk / Conditions | K1: Acceptance Gate
A2: Sprint 1 | B2: 46298 | C2: 46311 | D2: Chốt scope/actor/luồng, quy tắc nhóm và tài liệu PA1; chưa cam kết phát triển nhiều chức năng. | E2: CIN-T-001 Chốt phạm vi hệ thống và tác nhân; CIN-T-002 Đặc tả luồng nghiệp vụ khách hàng và quản trị; CIN-T-003 Baseline yêu cầu, use case và kiến trúc sơ bộ; CIN-T-012 Thiết lập quy tắc cộng tác và cấu trúc repository; CIN-T-047 Soạn tổng quan và phân tích nghiệp vụ cho PA1 | F2: Chốt phạm vi hệ thống và tác nhân: Xác định loại hệ thống, Xác định phạm vi hệ thống, Xác định Actor; Đặc tả luồng nghiệp vụ khách hàng và quản trị: Xác định đối tượng dữ liệu, Phân tích luồng khách hàng, Phân tích luồng quản trị; Baseline yêu cầu, use case và kiến trúc sơ bộ: Xác định chức năng hệ thống, Xác định yêu cầu phi chức năng, Xây dựng Use Case; Thiết lập quy tắc cộng tác và cấu trúc repository: Git Branching, Commit Convention, Pull Request; Soạn tổng quan và phân tích nghiệp vụ cho PA1: Tổng quan hệ thống, Phân tích nghiệp vụ | G2: CIN-T-001 → CIN-T-002; CIN-T-002 → CIN-T-003; CIN-T-003 → CIN-T-047 | H2: PA1: 16/10/2026 vs 17/10/2026 — confirm official date. | I2: =SUMIFS('Master Subtasks'!$V$2:$V$293,'Master Subtasks'!$Q$2:$Q$293,A2) | J2: Xung đột PA1: 16/10 trong lịch tổng thể và 17/10 trong tài liệu khác; cần xác nhận. | K2: Evidence reviewed; blockers/deferred scope explicitly accepted; milestone date/scope confirmed.
A3: Sprint 2 | B3: 46312 | C3: 46325 | D3: Hoàn tất baseline database/API/UI design và môi trường local có thể tái lập. | E3: CIN-T-004 Thiết kế dữ liệu phim, phòng, ghế và suất chiếu; CIN-T-005 Thiết kế dữ liệu booking, ticket, payment và user; CIN-T-006 Xác định quan hệ, ràng buộc và tính toàn vẹn dữ liệu; CIN-T-007 Hoàn tất ERD và relational schema; CIN-T-008 Thiết kế luồng, màn hình và điều hướng Customer; CIN-T-009 Đặc tả các màn hình Customer; CIN-T-010 Xác định component, UI state, dữ liệu và responsive behavior; CIN-T-011 Chốt API contract và chính sách truy cập; CIN-T-037 Chuẩn hóa môi trường phát triển local; CIN-T-042 Tạo README và tài liệu kiến trúc/database ban đầu; CIN-T-048 Soạn phần thiết kế hệ thống và database | F3: Thiết kế dữ liệu phim, phòng, ghế và suất chiếu: Thiết kế bảng, Thiết kế bảng Movie, Thiết kế bảng Genre; Thiết kế dữ liệu booking, ticket, payment và user: Thiết kế bảng Booking, Thiết kế bảng BookingDetail, Thiết kế bảng Ticket; Xác định quan hệ, ràng buộc và tính toàn vẹn dữ liệu: Thiết kế quan hệ, Xác định PK/FK, Xác định kiểu dữ liệu; Hoàn tất ERD và relational schema: Vẽ ERD, Hoàn thiện Relational Schema; Thiết kế luồng, màn hình và điều hướng Customer: Xác định Customer User Flow, Xác định danh sách màn hình Customer, Web Layout; Đặc tả các màn hình Customer: Trang Home, Trang Movie List, Trang Movie Detail; Xác định component, UI state, dữ liệu và responsive behavior: Xác định Component dùng chung, Xác định UI State, Xác định dữ liệu cần hiển thị; Chốt API contract và chính sách truy cập: Xác định API Contract, Thiết kế API Endpoint, Thiết kế Request / Response; Chuẩn hóa môi trường phát triển local: Docker PostgreSQL, Docker Backend, Docker Frontend; Tạo README và tài liệu kiến trúc/database ban đầu: README, Architecture Documentation, Database Documentation; Soạn phần thiết kế hệ thống và database: Thiết kế hệ thống, Thiết kế Database | G3: CIN-T-003 → CIN-T-004; CIN-T-004 → CIN-T-005; CIN-T-005 → CIN-T-006; CIN-T-006 → CIN-T-007; CIN-T-003 → CIN-T-008; CIN-T-008 → CIN-T-009; CIN-T-009 → CIN-T-010; CIN-T-007 → CIN-T-011; CIN-T-003 → CIN-T-011; CIN-T-012 → CIN-T-037; CIN-T-003 → CIN-T-037; CIN-T-007 → CIN-T-042; CIN-T-003 → CIN-T-042; CIN-T-007 → CIN-T-048; CIN-T-003 → CIN-T-048 | H3: PA2: 30/10/2026 appears in source schedule only — confirm. | I3: =SUMIFS('Master Subtasks'!$V$2:$V$293,'Master Subtasks'!$Q$2:$Q$293,A3) | J3: Thiết kế và môi trường có nhiều phụ thuộc; PA2/date/rubric chưa được xác nhận. | K3: Evidence reviewed; blockers/deferred scope explicitly accepted; milestone date/scope confirmed.
A4: Sprint 3 | B4: 46326 | C4: 46339 | D4: Khóa thiết kế chi tiết trước PA3; làm nền tảng backend/catalog/auth có giới hạn. | E4: CIN-T-013 Xây persistence và khởi tạo database bằng EF Core; CIN-T-014 Định nghĩa REST API và DTO foundation; CIN-T-015 Triển khai API phim, rạp, ghế, vé và lịch chiếu; CIN-T-018 Chuẩn hóa API response và tài liệu OpenAPI; CIN-T-019 Triển khai đăng ký, đăng nhập và phân quyền; CIN-T-020 Xây nghiệp vụ quản lý phim, phòng, ghế và loại vé; CIN-T-021 Xây nghiệp vụ suất chiếu và kiểm tra lịch; CIN-T-025 Xây giao diện xem phim và chọn suất chiếu; CIN-T-033 Áp dụng bảo vệ tài khoản, API, input và secrets; CIN-T-043 Hoàn thiện API và environment documentation | F4: Xây persistence và khởi tạo database bằng EF Core: Xây dựng Entity Models, Xây dựng AppDbContext, Cấu hình Relationships; Định nghĩa REST API và DTO foundation: Thiết kế REST API, Thiết kế DTO; Triển khai API phim, rạp, ghế, vé và lịch chiếu: API Movie / Genre, API Cinema Room, API Seat / Seat Type; Chuẩn hóa API response và tài liệu OpenAPI: Swagger / OpenAPI, API Response Convention; Triển khai đăng ký, đăng nhập và phân quyền: Register, Login, Password Hashing; Xây nghiệp vụ quản lý phim, phòng, ghế và loại vé: Quản lý Movie, Quản lý Genre, Quản lý Cinema Room; Xây nghiệp vụ suất chiếu và kiểm tra lịch: Tạo Showtime, Kiểm tra thời gian phim, Kiểm tra trùng lịch; Xây giao diện xem phim và chọn suất chiếu: Web Layout, Trang Home, Trang Movie List; Áp dụng bảo vệ tài khoản, API, input và secrets: Password Security, API Security, CORS; Hoàn thiện API và environment documentation: API Documentation, Environment Documentation | G4: CIN-T-007 → CIN-T-013; CIN-T-037 → CIN-T-013; CIN-T-011 → CIN-T-014; CIN-T-007 → CIN-T-014; CIN-T-013 → CIN-T-015; CIN-T-014 → CIN-T-015; CIN-T-014 → CIN-T-018; CIN-T-013 → CIN-T-019; CIN-T-014 → CIN-T-019; CIN-T-003 → CIN-T-019; CIN-T-015 → CIN-T-020; CIN-T-019 → CIN-T-020; CIN-T-020 → CIN-T-021; CIN-T-009 → CIN-T-025; CIN-T-015 → CIN-T-025; CIN-T-019 → CIN-T-033; CIN-T-014 → CIN-T-033; CIN-T-012 → CIN-T-033; CIN-T-014 → CIN-T-043; CIN-T-037 → CIN-T-043 | H4: PA3 – Detailed Design Baseline: 13/11/2026. | I4: =SUMIFS('Master Subtasks'!$V$2:$V$293,'Master Subtasks'!$Q$2:$Q$293,A4) | J4: PA3 là design baseline 13/11; xác nhận code nền có được làm trước PA3 không. | K4: Evidence reviewed; blockers/deferred scope explicitly accepted; milestone date/scope confirmed.
A5: Sprint 4 | B5: 46340 | C5: 46353 | D5: Hoàn thành luồng mua vé cốt lõi, tích hợp FE–BE và kiểm thử cho demo tích hợp. | E5: CIN-T-016 Triển khai API booking, ticket và payment; CIN-T-022 Triển khai chọn ghế, giữ chỗ và tạo booking an toàn; CIN-T-023 Triển khai thanh toán mô phỏng và trạng thái giao dịch; CIN-T-024 Phát hành, tạo mã/QR và xác thực vé; CIN-T-026 Xây giao diện ghế, thanh toán và tài khoản; CIN-T-027 Tích hợp frontend với API thật; CIN-T-032 Chuẩn hóa validation và xử lý lỗi backend/frontend; CIN-T-035 Kiểm thử unit, integration và luồng đặt vé cốt lõi | F5: Triển khai API booking, ticket và payment: API Booking, API Booking Detail, API Ticket; Triển khai chọn ghế, giữ chỗ và tạo booking an toàn: Chọn ghế, Seat Availability, Giữ ghế; Triển khai thanh toán mô phỏng và trạng thái giao dịch: Thiết kế Payment Flow, Tích hợp Payment Gateway, Payment Callback / Webhook; Phát hành, tạo mã/QR và xác thực vé: Phát hành Ticket, Generate Ticket Code, Generate QR Code; Xây giao diện ghế, thanh toán và tài khoản: Trang Seat Selection, Trang Ticket Type, Trang Booking Confirmation; Tích hợp frontend với API thật: API Client, Authentication Integration, Loading State; Chuẩn hóa validation và xử lý lỗi backend/frontend: Backend Validation, Frontend Validation, Global Exception Handling; Kiểm thử unit, integration và luồng đặt vé cốt lõi: Unit Test, Integration Test, Authentication Test | G5: CIN-T-015 → CIN-T-016; CIN-T-022 → CIN-T-016; CIN-T-023 → CIN-T-016; CIN-T-021 → CIN-T-022; CIN-T-019 → CIN-T-022; CIN-T-014 → CIN-T-022; CIN-T-022 → CIN-T-023; CIN-T-023 → CIN-T-024; CIN-T-022 → CIN-T-024; CIN-T-025 → CIN-T-026; CIN-T-022 → CIN-T-026; CIN-T-023 → CIN-T-026; CIN-T-024 → CIN-T-026; CIN-T-026 → CIN-T-027; CIN-T-016 → CIN-T-027; CIN-T-019 → CIN-T-027; CIN-T-014 → CIN-T-032; CIN-T-022 → CIN-T-032; CIN-T-023 → CIN-T-032; CIN-T-020 → CIN-T-035; CIN-T-021 → CIN-T-035; CIN-T-022 → CIN-T-035; CIN-T-023 → CIN-T-035; CIN-T-024 → CIN-T-035; CIN-T-027 → CIN-T-035 | H5: PA4 – Integrated Demo: 27/11/2026. | I5: =SUMIFS('Master Subtasks'!$V$2:$V$293,'Master Subtasks'!$Q$2:$Q$293,A5) | J5: Booking concurrency, payment result và ticket issuance là rủi ro; baseline chỉ dùng payment mô phỏng. | K5: Evidence reviewed; blockers/deferred scope explicitly accepted; milestone date/scope confirmed.
A6: Sprint 5 | B6: 46354 | C6: 46368 | D6: Ổn định, hoàn thiện admin/deploy/demo/tài liệu/báo cáo; tính năng tùy chọn chỉ làm khi còn năng lực. | E6: CIN-T-017 Triển khai API user và statistics cơ bản; CIN-T-028 Xây giao diện quản trị và nhân viên tối thiểu; CIN-T-029 Bổ sung tìm kiếm và bộ lọc cần thiết; CIN-T-030 Xây báo cáo cơ bản và đánh giá export; CIN-T-031 Đánh giá và triển khai AI movie assistant tùy chọn; CIN-T-034 Đánh giá security headers nâng cao; CIN-T-036 Chạy kiểm thử hồi quy trước khi bàn giao; CIN-T-038 Tự động hóa build, test và kiểm tra chất lượng; CIN-T-039 Chuẩn bị và xác minh môi trường triển khai demo; CIN-T-040 Hoàn thiện hosting và xác nhận triển khai; CIN-T-041 Đánh giá logging, health, backup và vận hành; CIN-T-044 Hoàn thiện hướng dẫn triển khai và sử dụng; CIN-T-045 Tích hợp toàn hệ thống và xử lý lỗi release; CIN-T-046 Chuẩn bị dữ liệu, tài khoản và kịch bản demo; CIN-T-049 Hoàn thiện chương kỹ thuật và triển khai trong báo cáo; CIN-T-050 Hoàn thiện đánh giá, slide và phân công thuyết trình | F6: Triển khai API user và statistics cơ bản: API User, API Statistics; Xây giao diện quản trị và nhân viên tối thiểu: Admin Layout, Dashboard, Quản lý Movie; Bổ sung tìm kiếm và bộ lọc cần thiết: Tìm kiếm phim, Lọc phim, Lọc Showtime; Xây báo cáo cơ bản và đánh giá export: Dashboard Statistics, Thống kê doanh thu, Thống kê vé; Đánh giá và triển khai AI movie assistant tùy chọn: Xác định chức năng AI, AI Movie Assistant, AI Movie Recommendation; Đánh giá security headers nâng cao: Security Headers; Chạy kiểm thử hồi quy trước khi bàn giao: Regression Test; Tự động hóa build, test và kiểm tra chất lượng: Thiết lập CI, Backend Build, Frontend Build; Chuẩn bị và xác minh môi trường triển khai demo: Chuẩn bị Production Server, Deploy Backend, Deploy Frontend; Hoàn thiện hosting và xác nhận triển khai: Domain, DNS, HTTPS / SSL; Đánh giá logging, health, backup và vận hành: Health Check, Logging, Error Monitoring; Hoàn thiện hướng dẫn triển khai và sử dụng: Deployment Documentation, User Guide; Tích hợp toàn hệ thống và xử lý lỗi release: Merge toàn bộ module, Kiểm tra API Integration, Kiểm tra Authentication; Chuẩn bị dữ liệu, tài khoản và kịch bản demo: Chuẩn bị tài khoản Demo, Chuẩn bị dữ liệu Demo, Chuẩn bị kịch bản Demo; Hoàn thiện chương kỹ thuật và triển khai trong báo cáo: Backend, Frontend, Authentication / Security; Hoàn thiện đánh giá, slide và phân công thuyết trình: Đánh giá hệ thống, Hình ảnh minh họa, Chuẩn bị Slide | G6: CIN-T-019 → CIN-T-017; CIN-T-015 → CIN-T-017; CIN-T-019 → CIN-T-028; CIN-T-020 → CIN-T-028; CIN-T-021 → CIN-T-028; CIN-T-017 → CIN-T-028; CIN-T-015 → CIN-T-029; CIN-T-028 → CIN-T-029; CIN-T-017 → CIN-T-030; CIN-T-023 → CIN-T-030; CIN-T-024 → CIN-T-030; CIN-T-025 → CIN-T-031; CIN-T-029 → CIN-T-031; CIN-T-033 → CIN-T-034; CIN-T-035 → CIN-T-036; CIN-T-028 → CIN-T-036; CIN-T-029 → CIN-T-036; CIN-T-030 → CIN-T-036; CIN-T-035 → CIN-T-038; CIN-T-012 → CIN-T-038; CIN-T-037 → CIN-T-039; CIN-T-038 → CIN-T-039; CIN-T-027 → CIN-T-039; CIN-T-039 → CIN-T-040; CIN-T-039 → CIN-T-041; CIN-T-039 → CIN-T-044; CIN-T-028 → CIN-T-044; CIN-T-027 → CIN-T-045; CIN-T-035 → CIN-T-045; CIN-T-028 → CIN-T-045; CIN-T-039 → CIN-T-045; CIN-T-045 → CIN-T-046; CIN-T-030 → CIN-T-046; CIN-T-045 → CIN-T-049; CIN-T-036 → CIN-T-049; CIN-T-044 → CIN-T-049; CIN-T-049 → CIN-T-050; CIN-T-046 → CIN-T-050 | H6: PA5 – Final Build: 12/12/2026. | I6: =SUMIFS('Master Subtasks'!$V$2:$V$293,'Master Subtasks'!$Q$2:$Q$293,A6) | J6: Sprint tải cao; gateway thật, AI, refund, production hosting và operations có thể phải defer. | K6: Evidence reviewed; blockers/deferred scope explicitly accepted; milestone date/scope confirmed.

Sheet Member Workload
A1: Member ID | B1: Member Name | C1: Role | D1: Sprint 1 (SP) | E1: Sprint 2 (SP) | F1: Sprint 3 (SP) | G1: Sprint 4 (SP) | H1: Sprint 5 (SP) | I1: Total (SP) | J1: Share of Team | K1: Capacity / Balance Note
A2: 24120235 | B2: Huynh Thanh Tu | C2: Project Manager | D2: =SUMIFS('Master Subtasks'!$V$2:$V$293,'Master Subtasks'!$R$2:$R$293,$A2,'Master Subtasks'!$Q$2:$Q$293,"Sprint 1") | E2: =SUMIFS('Master Subtasks'!$V$2:$V$293,'Master Subtasks'!$R$2:$R$293,$A2,'Master Subtasks'!$Q$2:$Q$293,"Sprint 2") | F2: =SUMIFS('Master Subtasks'!$V$2:$V$293,'Master Subtasks'!$R$2:$R$293,$A2,'Master Subtasks'!$Q$2:$Q$293,"Sprint 3") | G2: =SUMIFS('Master Subtasks'!$V$2:$V$293,'Master Subtasks'!$R$2:$R$293,$A2,'Master Subtasks'!$Q$2:$Q$293,"Sprint 4") | H2: =SUMIFS('Master Subtasks'!$V$2:$V$293,'Master Subtasks'!$R$2:$R$293,$A2,'Master Subtasks'!$Q$2:$Q$293,"Sprint 5") | I2: =SUM(D2:H2) | J2: =IFERROR(I2/$I$7,0) | K2: =IF(MAX(D2:H2)>20,"Review: peak sprint load exceeds provisional 20-SP guardrail; confirm availability or re-scope.","No sprint exceeds provisional guardrail; confirm availability.")
A3: 24120098 | B3: Nguyen Quoc Nam | C3: Team Member | D3: =SUMIFS('Master Subtasks'!$V$2:$V$293,'Master Subtasks'!$R$2:$R$293,$A3,'Master Subtasks'!$Q$2:$Q$293,"Sprint 1") | E3: =SUMIFS('Master Subtasks'!$V$2:$V$293,'Master Subtasks'!$R$2:$R$293,$A3,'Master Subtasks'!$Q$2:$Q$293,"Sprint 2") | F3: =SUMIFS('Master Subtasks'!$V$2:$V$293,'Master Subtasks'!$R$2:$R$293,$A3,'Master Subtasks'!$Q$2:$Q$293,"Sprint 3") | G3: =SUMIFS('Master Subtasks'!$V$2:$V$293,'Master Subtasks'!$R$2:$R$293,$A3,'Master Subtasks'!$Q$2:$Q$293,"Sprint 4") | H3: =SUMIFS('Master Subtasks'!$V$2:$V$293,'Master Subtasks'!$R$2:$R$293,$A3,'Master Subtasks'!$Q$2:$Q$293,"Sprint 5") | I3: =SUM(D3:H3) | J3: =IFERROR(I3/$I$7,0) | K3: =IF(MAX(D3:H3)>20,"Review: peak sprint load exceeds provisional 20-SP guardrail; confirm availability or re-scope.","No sprint exceeds provisional guardrail; confirm availability.")
A4: 24120271 | B4: Nguyen Trung Chinh | C4: Team Member | D4: =SUMIFS('Master Subtasks'!$V$2:$V$293,'Master Subtasks'!$R$2:$R$293,$A4,'Master Subtasks'!$Q$2:$Q$293,"Sprint 1") | E4: =SUMIFS('Master Subtasks'!$V$2:$V$293,'Master Subtasks'!$R$2:$R$293,$A4,'Master Subtasks'!$Q$2:$Q$293,"Sprint 2") | F4: =SUMIFS('Master Subtasks'!$V$2:$V$293,'Master Subtasks'!$R$2:$R$293,$A4,'Master Subtasks'!$Q$2:$Q$293,"Sprint 3") | G4: =SUMIFS('Master Subtasks'!$V$2:$V$293,'Master Subtasks'!$R$2:$R$293,$A4,'Master Subtasks'!$Q$2:$Q$293,"Sprint 4") | H4: =SUMIFS('Master Subtasks'!$V$2:$V$293,'Master Subtasks'!$R$2:$R$293,$A4,'Master Subtasks'!$Q$2:$Q$293,"Sprint 5") | I4: =SUM(D4:H4) | J4: =IFERROR(I4/$I$7,0) | K4: =IF(MAX(D4:H4)>20,"Review: peak sprint load exceeds provisional 20-SP guardrail; confirm availability or re-scope.","No sprint exceeds provisional guardrail; confirm availability.")
